<?xml version="1.0"?>

<robot name="DoublePendulum">
	<link name="base_link">
		<visual>
			<geometry>
				 <box size="1 .2 .2" />
			</geometry>
			<material name="green">
				 <color rgba="0 1 0 .5" />
			</material>
		</visual>
	</link>

  <link name="link1">
    <inertial>
      <origin xyz="0 0 -0.5" rpy="0 0. 0." />
      <mass value="1" />
      <inertia ixx=".0841667" ixy="0" ixz="0" iyy=".0841667" iyz="0" izz=".00166667" />
    </inertial>
    <visual>
      <origin xyz="0 0 -0.5" rpy="0. 0 0." />
      <geometry>
         <cylinder length="1" radius=".05" />
      </geometry>
      <material name="green">
	       <color rgba="1 0 1 1" />
      </material>
    </visual>
  </link>

	<link name="link2">
    <inertial>
      <origin xyz="0 0 -0.5" rpy="0 0. 0." />
      <mass value="1" />
      <inertia ixx=".0841667" ixy="0" ixz="0" iyy=".0841667" iyz="0" izz=".00166667" />
    </inertial>
    <visual>
      <origin xyz="0 0 -0.5" rpy="0. 0 0." />
      <geometry>
         <cylinder length="1" radius=".05" />
      </geometry>
      <material name="green">
	       <color rgba="1 0 1 1" />
      </material>
    </visual>
  </link>

	<link name="link3">
    <inertial>
      <origin xyz="0 0 -0.5" rpy="0 0. 0." />
      <mass value="1" />
      <inertia ixx=".0841667" ixy="0" ixz="0" iyy=".0841667" iyz="0" izz=".00166667" />
    </inertial>
    <visual>
      <origin xyz="0 0 -0.5" rpy="0. 0 0." />
      <geometry>
         <cylinder length="1" radius=".05" />
      </geometry>
      <material name="red">
	       <color rgba="1 0 0 1" />
      </material>
    </visual>
  </link>

	<link name="link4">
    <inertial>
      <origin xyz="0 0 -0.5" rpy="0 0. 0." />
      <mass value="1" />
      <inertia ixx=".0841667" ixy="0" ixz="0" iyy=".0841667" iyz="0" izz=".00166667" />
    </inertial>
    <visual>
      <origin xyz="0 0 -0.5" rpy="0. 0 0." />
      <geometry>
         <cylinder length="1" radius=".05" />
      </geometry>
      <material name="red">
	       <color rgba="1 0 0 1" />
      </material>
    </visual>
  </link>

	<joint name="joint1" type="continuous">
		<parent link="base_link" />
		<child link="link1" />
		<origin xyz="0 0 0" />
		<axis xyz="1 0 0" />
		<dynamics damping="0"/>
	</joint>

	<joint name="joint2" type="continuous">
		<parent link="link1" />
		<child link="link2" />
		<origin xyz="0 0 -1" />
		<axis xyz="1 0 0" />
		<dynamics damping="0"/>
	</joint>

	<joint name="joint3" type="continuous">
		<parent link="base_link" />
		<child link="link3" />
		<origin xyz="0 0 0" />
		<axis xyz="1 0 0" />
		<dynamics damping="0"/>
	</joint>

	<joint name="joint4" type="continuous">
		<parent link="link3" />
		<child link="link4" />
		<origin xyz="0 0 -1" />
		<axis xyz="1 0 0" />
		<dynamics damping="0"/>
	</joint>

</robot>
